Thu Oct 31 13:03:06 CST 2024 : Apache Derby Network Server - 10.17.1.0 - (1913217) started and ready to accept connections on port 1527
----------------------------------------------------------------
Thu Oct 31 13:03:09 CST 2024:
Booting Derby version The Apache Software Foundation - Apache Derby - 10.17.1.0 - (1913217): instance a816c00e-0192-e3f5-bd33-0000075846b0 
on database directory /Users/coleexz/Documents/GitHub/ApacheDerbyDBMS/db-derby-10.17.1.0-bin/bin/myNewDB with class loader jdk.internal.loader.ClassLoaders$AppClassLoader@1cf4f579 
Loaded from file:/Users/coleexz/Documents/GitHub/ApacheDerbyDBMS/db-derby-10.17.1.0-bin/lib/derby.jar
java.vendor=Oracle Corporation
java.runtime.version=21.0.4+8-LTS-274
user.dir=/Users/coleexz/Documents/GitHub/ApacheDerbyDBMS/db-derby-10.17.1.0-bin/bin
os.name=Mac OS X
os.arch=aarch64
os.version=15.0.1
derby.system.home=null
Database Class Loader started - derby.database.classpath=''
Thu Oct 31 13:16:49 CST 2024 Thread[#31,DRDAConnThread_3,5,main] (XID = 4088), (SESSIONID = 4), (DATABASE = myNewDB), (DRDAID = {3}), Cleanup action starting
java.sql.SQLNonTransientConnectionException: Connection authentication failure occurred.  Reason: Invalid authentication..
	at org.apache.derby.impl.jdbc.SQLExceptionFactory.getSQLException(SQLExceptionFactory.java:81)
	at org.apache.derby.impl.jdbc.SQLExceptionFactory.getSQLException(SQLExceptionFactory.java:141)
	at org.apache.derby.impl.jdbc.Util.generateCsSQLException(Util.java:225)
	at org.apache.derby.impl.jdbc.Util.generateCsSQLException(Util.java:220)
	at org.apache.derby.impl.jdbc.EmbedConnection.newSQLException(EmbedConnection.java:3208)
	at org.apache.derby.impl.jdbc.EmbedConnection.checkUserCredentials(EmbedConnection.java:1315)
	at org.apache.derby.impl.jdbc.EmbedConnection.<init>(EmbedConnection.java:445)
	at org.apache.derby.iapi.jdbc.InternalDriver.getNewEmbedConnection(InternalDriver.java:629)
	at org.apache.derby.iapi.jdbc.InternalDriver.connect(InternalDriver.java:295)
	at org.apache.derby.iapi.jdbc.InternalDriver.connect(InternalDriver.java:921)
	at org.apache.derby.jdbc.EmbeddedDriver.connect(EmbeddedDriver.java:125)
	at org.apache.derby.impl.drda.Database.makeConnection(Database.java:253)
	at org.apache.derby.impl.drda.DRDAConnThread.getConnFromDatabaseName(DRDAConnThread.java:1474)
	at org.apache.derby.impl.drda.DRDAConnThread.verifyUserIdPassword(DRDAConnThread.java:1424)
	at org.apache.derby.impl.drda.DRDAConnThread.parseSECCHK(DRDAConnThread.java:3378)
	at org.apache.derby.impl.drda.DRDAConnThread.parseDRDAConnection(DRDAConnThread.java:1208)
	at org.apache.derby.impl.drda.DRDAConnThread.processCommands(DRDAConnThread.java:1008)
	at org.apache.derby.impl.drda.DRDAConnThread.run(DRDAConnThread.java:298)
Caused by: ERROR 08004: Connection authentication failure occurred.  Reason: Invalid authentication..
	at org.apache.derby.shared.common.error.StandardException.newException(StandardException.java:299)
	at org.apache.derby.impl.jdbc.SQLExceptionFactory.wrapArgsForTransportAcrossDRDA(SQLExceptionFactory.java:170)
	at org.apache.derby.impl.jdbc.SQLExceptionFactory.getSQLException(SQLExceptionFactory.java:75)
	... 17 more
============= begin nested exception, level (1) ===========
ERROR 08004: Connection authentication failure occurred.  Reason: Invalid authentication..
	at org.apache.derby.shared.common.error.StandardException.newException(StandardException.java:299)
	at org.apache.derby.impl.jdbc.SQLExceptionFactory.wrapArgsForTransportAcrossDRDA(SQLExceptionFactory.java:170)
	at org.apache.derby.impl.jdbc.SQLExceptionFactory.getSQLException(SQLExceptionFactory.java:75)
	at org.apache.derby.impl.jdbc.SQLExceptionFactory.getSQLException(SQLExceptionFactory.java:141)
	at org.apache.derby.impl.jdbc.Util.generateCsSQLException(Util.java:225)
	at org.apache.derby.impl.jdbc.Util.generateCsSQLException(Util.java:220)
	at org.apache.derby.impl.jdbc.EmbedConnection.newSQLException(EmbedConnection.java:3208)
	at org.apache.derby.impl.jdbc.EmbedConnection.checkUserCredentials(EmbedConnection.java:1315)
	at org.apache.derby.impl.jdbc.EmbedConnection.<init>(EmbedConnection.java:445)
	at org.apache.derby.iapi.jdbc.InternalDriver.getNewEmbedConnection(InternalDriver.java:629)
	at org.apache.derby.iapi.jdbc.InternalDriver.connect(InternalDriver.java:295)
	at org.apache.derby.iapi.jdbc.InternalDriver.connect(InternalDriver.java:921)
	at org.apache.derby.jdbc.EmbeddedDriver.connect(EmbeddedDriver.java:125)
	at org.apache.derby.impl.drda.Database.makeConnection(Database.java:253)
	at org.apache.derby.impl.drda.DRDAConnThread.getConnFromDatabaseName(DRDAConnThread.java:1474)
	at org.apache.derby.impl.drda.DRDAConnThread.verifyUserIdPassword(DRDAConnThread.java:1424)
	at org.apache.derby.impl.drda.DRDAConnThread.parseSECCHK(DRDAConnThread.java:3378)
	at org.apache.derby.impl.drda.DRDAConnThread.parseDRDAConnection(DRDAConnThread.java:1208)
	at org.apache.derby.impl.drda.DRDAConnThread.processCommands(DRDAConnThread.java:1008)
	at org.apache.derby.impl.drda.DRDAConnThread.run(DRDAConnThread.java:298)
============= end nested exception, level (1) ===========
Cleanup action completed
Thu Oct 31 13:16:49 CST 2024 Thread[#31,DRDAConnThread_3,5,main] (DATABASE = myNewDB), (DRDAID = {3}), Connection authentication failure occurred.  Reason: Invalid authentication..
Thu Oct 31 13:19:39 CST 2024 Thread[#31,DRDAConnThread_3,5,main] (XID = 4103), (SESSIONID = 9), (DATABASE = myNewDB), (DRDAID = {6}), Cleanup action starting
java.sql.SQLNonTransientConnectionException: Connection authentication failure occurred.  Reason: Invalid authentication..
	at org.apache.derby.impl.jdbc.SQLExceptionFactory.getSQLException(SQLExceptionFactory.java:81)
	at org.apache.derby.impl.jdbc.SQLExceptionFactory.getSQLException(SQLExceptionFactory.java:141)
	at org.apache.derby.impl.jdbc.Util.generateCsSQLException(Util.java:225)
	at org.apache.derby.impl.jdbc.Util.generateCsSQLException(Util.java:220)
	at org.apache.derby.impl.jdbc.EmbedConnection.newSQLException(EmbedConnection.java:3208)
	at org.apache.derby.impl.jdbc.EmbedConnection.checkUserCredentials(EmbedConnection.java:1315)
	at org.apache.derby.impl.jdbc.EmbedConnection.<init>(EmbedConnection.java:445)
	at org.apache.derby.iapi.jdbc.InternalDriver.getNewEmbedConnection(InternalDriver.java:629)
	at org.apache.derby.iapi.jdbc.InternalDriver.connect(InternalDriver.java:295)
	at org.apache.derby.iapi.jdbc.InternalDriver.connect(InternalDriver.java:921)
	at org.apache.derby.jdbc.EmbeddedDriver.connect(EmbeddedDriver.java:125)
	at org.apache.derby.impl.drda.Database.makeConnection(Database.java:253)
	at org.apache.derby.impl.drda.DRDAConnThread.getConnFromDatabaseName(DRDAConnThread.java:1474)
	at org.apache.derby.impl.drda.DRDAConnThread.verifyUserIdPassword(DRDAConnThread.java:1424)
	at org.apache.derby.impl.drda.DRDAConnThread.parseSECCHK(DRDAConnThread.java:3378)
	at org.apache.derby.impl.drda.DRDAConnThread.parseDRDAConnection(DRDAConnThread.java:1208)
	at org.apache.derby.impl.drda.DRDAConnThread.processCommands(DRDAConnThread.java:1008)
	at org.apache.derby.impl.drda.DRDAConnThread.run(DRDAConnThread.java:298)
Caused by: ERROR 08004: Connection authentication failure occurred.  Reason: Invalid authentication..
	at org.apache.derby.shared.common.error.StandardException.newException(StandardException.java:299)
	at org.apache.derby.impl.jdbc.SQLExceptionFactory.wrapArgsForTransportAcrossDRDA(SQLExceptionFactory.java:170)
	at org.apache.derby.impl.jdbc.SQLExceptionFactory.getSQLException(SQLExceptionFactory.java:75)
	... 17 more
============= begin nested exception, level (1) ===========
ERROR 08004: Connection authentication failure occurred.  Reason: Invalid authentication..
	at org.apache.derby.shared.common.error.StandardException.newException(StandardException.java:299)
	at org.apache.derby.impl.jdbc.SQLExceptionFactory.wrapArgsForTransportAcrossDRDA(SQLExceptionFactory.java:170)
	at org.apache.derby.impl.jdbc.SQLExceptionFactory.getSQLException(SQLExceptionFactory.java:75)
	at org.apache.derby.impl.jdbc.SQLExceptionFactory.getSQLException(SQLExceptionFactory.java:141)
	at org.apache.derby.impl.jdbc.Util.generateCsSQLException(Util.java:225)
	at org.apache.derby.impl.jdbc.Util.generateCsSQLException(Util.java:220)
	at org.apache.derby.impl.jdbc.EmbedConnection.newSQLException(EmbedConnection.java:3208)
	at org.apache.derby.impl.jdbc.EmbedConnection.checkUserCredentials(EmbedConnection.java:1315)
	at org.apache.derby.impl.jdbc.EmbedConnection.<init>(EmbedConnection.java:445)
	at org.apache.derby.iapi.jdbc.InternalDriver.getNewEmbedConnection(InternalDriver.java:629)
	at org.apache.derby.iapi.jdbc.InternalDriver.connect(InternalDriver.java:295)
	at org.apache.derby.iapi.jdbc.InternalDriver.connect(InternalDriver.java:921)
	at org.apache.derby.jdbc.EmbeddedDriver.connect(EmbeddedDriver.java:125)
	at org.apache.derby.impl.drda.Database.makeConnection(Database.java:253)
	at org.apache.derby.impl.drda.DRDAConnThread.getConnFromDatabaseName(DRDAConnThread.java:1474)
	at org.apache.derby.impl.drda.DRDAConnThread.verifyUserIdPassword(DRDAConnThread.java:1424)
	at org.apache.derby.impl.drda.DRDAConnThread.parseSECCHK(DRDAConnThread.java:3378)
	at org.apache.derby.impl.drda.DRDAConnThread.parseDRDAConnection(DRDAConnThread.java:1208)
	at org.apache.derby.impl.drda.DRDAConnThread.processCommands(DRDAConnThread.java:1008)
	at org.apache.derby.impl.drda.DRDAConnThread.run(DRDAConnThread.java:298)
============= end nested exception, level (1) ===========
Cleanup action completed
Thu Oct 31 13:19:39 CST 2024 Thread[#31,DRDAConnThread_3,5,main] (DATABASE = myNewDB), (DRDAID = {6}), Connection authentication failure occurred.  Reason: Invalid authentication..
Thu Oct 31 13:25:11 CST 2024 Thread[#31,DRDAConnThread_3,5,main] (XID = 4116), (SESSIONID = 16), (DATABASE = myNewDB), (DRDAID = {10}), Cleanup action starting
java.sql.SQLNonTransientConnectionException: Connection authentication failure occurred.  Reason: Invalid authentication..
	at org.apache.derby.impl.jdbc.SQLExceptionFactory.getSQLException(SQLExceptionFactory.java:81)
	at org.apache.derby.impl.jdbc.SQLExceptionFactory.getSQLException(SQLExceptionFactory.java:141)
	at org.apache.derby.impl.jdbc.Util.generateCsSQLException(Util.java:225)
	at org.apache.derby.impl.jdbc.Util.generateCsSQLException(Util.java:220)
	at org.apache.derby.impl.jdbc.EmbedConnection.newSQLException(EmbedConnection.java:3208)
	at org.apache.derby.impl.jdbc.EmbedConnection.checkUserCredentials(EmbedConnection.java:1315)
	at org.apache.derby.impl.jdbc.EmbedConnection.<init>(EmbedConnection.java:445)
	at org.apache.derby.iapi.jdbc.InternalDriver.getNewEmbedConnection(InternalDriver.java:629)
	at org.apache.derby.iapi.jdbc.InternalDriver.connect(InternalDriver.java:295)
	at org.apache.derby.iapi.jdbc.InternalDriver.connect(InternalDriver.java:921)
	at org.apache.derby.jdbc.EmbeddedDriver.connect(EmbeddedDriver.java:125)
	at org.apache.derby.impl.drda.Database.makeConnection(Database.java:253)
	at org.apache.derby.impl.drda.DRDAConnThread.getConnFromDatabaseName(DRDAConnThread.java:1474)
	at org.apache.derby.impl.drda.DRDAConnThread.verifyUserIdPassword(DRDAConnThread.java:1424)
	at org.apache.derby.impl.drda.DRDAConnThread.parseSECCHK(DRDAConnThread.java:3378)
	at org.apache.derby.impl.drda.DRDAConnThread.parseDRDAConnection(DRDAConnThread.java:1208)
	at org.apache.derby.impl.drda.DRDAConnThread.processCommands(DRDAConnThread.java:1008)
	at org.apache.derby.impl.drda.DRDAConnThread.run(DRDAConnThread.java:298)
Caused by: ERROR 08004: Connection authentication failure occurred.  Reason: Invalid authentication..
	at org.apache.derby.shared.common.error.StandardException.newException(StandardException.java:299)
	at org.apache.derby.impl.jdbc.SQLExceptionFactory.wrapArgsForTransportAcrossDRDA(SQLExceptionFactory.java:170)
	at org.apache.derby.impl.jdbc.SQLExceptionFactory.getSQLException(SQLExceptionFactory.java:75)
	... 17 more
============= begin nested exception, level (1) ===========
ERROR 08004: Connection authentication failure occurred.  Reason: Invalid authentication..
	at org.apache.derby.shared.common.error.StandardException.newException(StandardException.java:299)
	at org.apache.derby.impl.jdbc.SQLExceptionFactory.wrapArgsForTransportAcrossDRDA(SQLExceptionFactory.java:170)
	at org.apache.derby.impl.jdbc.SQLExceptionFactory.getSQLException(SQLExceptionFactory.java:75)
	at org.apache.derby.impl.jdbc.SQLExceptionFactory.getSQLException(SQLExceptionFactory.java:141)
	at org.apache.derby.impl.jdbc.Util.generateCsSQLException(Util.java:225)
	at org.apache.derby.impl.jdbc.Util.generateCsSQLException(Util.java:220)
	at org.apache.derby.impl.jdbc.EmbedConnection.newSQLException(EmbedConnection.java:3208)
	at org.apache.derby.impl.jdbc.EmbedConnection.checkUserCredentials(EmbedConnection.java:1315)
	at org.apache.derby.impl.jdbc.EmbedConnection.<init>(EmbedConnection.java:445)
	at org.apache.derby.iapi.jdbc.InternalDriver.getNewEmbedConnection(InternalDriver.java:629)
	at org.apache.derby.iapi.jdbc.InternalDriver.connect(InternalDriver.java:295)
	at org.apache.derby.iapi.jdbc.InternalDriver.connect(InternalDriver.java:921)
	at org.apache.derby.jdbc.EmbeddedDriver.connect(EmbeddedDriver.java:125)
	at org.apache.derby.impl.drda.Database.makeConnection(Database.java:253)
	at org.apache.derby.impl.drda.DRDAConnThread.getConnFromDatabaseName(DRDAConnThread.java:1474)
	at org.apache.derby.impl.drda.DRDAConnThread.verifyUserIdPassword(DRDAConnThread.java:1424)
	at org.apache.derby.impl.drda.DRDAConnThread.parseSECCHK(DRDAConnThread.java:3378)
	at org.apache.derby.impl.drda.DRDAConnThread.parseDRDAConnection(DRDAConnThread.java:1208)
	at org.apache.derby.impl.drda.DRDAConnThread.processCommands(DRDAConnThread.java:1008)
	at org.apache.derby.impl.drda.DRDAConnThread.run(DRDAConnThread.java:298)
============= end nested exception, level (1) ===========
Cleanup action completed
Thu Oct 31 13:25:11 CST 2024 Thread[#31,DRDAConnThread_3,5,main] (DATABASE = myNewDB), (DRDAID = {10}), Connection authentication failure occurred.  Reason: Invalid authentication..
